Workbook
Name A: SubCategoryList!$A$1
Name B: SubCategoryList!$B$1:$B$3
Name CC: SubCategoryList!$C$1:$C$3
Name D: SubCategoryList!$D$1:$D$4
Name E: SubCategoryList!$E$1:$E$2
Name Ear_NCB: DropdownValues!$B$2:$B$14
Name EH: SubCategoryList!$F$1:$F$2
Name EX_THI_PA: DropdownValues!$C$2:$C$6
Name F: SubCategoryList!$G$1:$G$6
Name G: SubCategoryList!$H$1:$H$3
Name good_covers: DropdownValues!$D$2:$D$7
Name H: SubCategoryList!$I$1:$I$31
Name I: SubCategoryList!$J$5
Name LLTP: DropdownValues!$A$2:$A$8
Name MR: DropdownValues!$E$2:$E$9

Sheet Vehicles
A1: FDVNO1 | B1: FDVNO2 | C1: FDPROV | D1: FD_Vehicle_Or_Trailor | E1: FD_Trailer_PROV | F1: FDYOM | G1: FD_Trailer_VNO1 | H1: FD_Trailer_VNO2 | I1: FDCHANO | J1: POLICYTYPENAME | K1: POLID | L1: FDVEHITYPE | M1: FDVEHIID | N1: SUBCATE | O1: FDBUSITYPE | P1: FDVEHVAL | Q1: FDTRAVAL | R1: FDNUMPASSEN
A2: SP | B2: 1234 | C2: WP | D2: T | E2: WP | J2: Comprehensive Policy | K2: =_xlfn.XLOOKUP(J2,CoverList!I:I,CoverList!H:H,"") -> 1 | L2: Private Car | M2: =_xlfn.XLOOKUP(L2,CoverList!M:M,CoverList!N:N,"") -> A | N2: Private Car | O2: =_xlfn.XLOOKUP(N2,CoverList!O:O,CoverList!P:P,"") -> AA0 | P2: 5500000 | Q2: 0 | R2: 0
A3: SP | B3: 1234 | C3: WP | D3: V | E3: SP | J3: Comprehensive Policy | K3: =_xlfn.XLOOKUP(J3,CoverList!I:I,CoverList!H:H,"") -> 1 | L3: Private Car | M3: =_xlfn.XLOOKUP(L3,CoverList!M:M,CoverList!N:N,"") -> A | N3: Private Car | O3: =_xlfn.XLOOKUP(N3,CoverList!O:O,CoverList!P:P,"") -> AA0 | P3: 6800000 | Q3: 0 | R3: 0
A4: SP | B4: 1234 | C4: WP | D4: V | E4: SG | J4: Third Party | K4: =_xlfn.XLOOKUP(J4,CoverList!I:I,CoverList!H:H,"") -> 2 | L4: Private Car | M4: =_xlfn.XLOOKUP(L4,CoverList!M:M,CoverList!N:N,"") -> A | N4: Private Car | O4: =_xlfn.XLOOKUP(N4,CoverList!O:O,CoverList!P:P,"") -> AA0 | P4: 5900000 | Q4: 0 | R4: 0

Sheet Sheet1

Sheet Covers
A1: FDVNO1 | B1: FDVNO2 | C1: Cover | D1: COVER_CODE | E1: TYPE | F1: COVVALUE | G1: COVPREC | H1: MAXVAL | I1: NOOFPASS | J1: IS_SELECTED | K1: RATECODE
A2: SP | B2: 1234 | C2: Terrorism Risk | D2: =_xlfn.XLOOKUP(C2,CoverList!B:B,CoverList!A:A,"") -> TR | E2: =_xlfn.XLOOKUP(C2,CoverList!B:B,CoverList!C:C,"") -> NORMAL | J2: Y | K2: =_xlfn.XLOOKUP(C2,CoverList!B:B,CoverList!D:D,"") -> MRTR1
A3: SP | B3: 1234 | C3: Excluded Items Cover | D3: =_xlfn.XLOOKUP(C3,CoverList!B:B,CoverList!A:A,"") -> EX_IT_COV | E3: =IFERROR(VLOOKUP(D3,CoverList!A:C,3,FALSE),"") -> NORMAL | J3: N | K3: =IFERROR(VLOOKUP(D3,CoverList!A:D,4,FALSE),"") -> MREXC
A4: SP | B4: 1234 | C4: Earn No Claim Bonus | D4: =_xlfn.XLOOKUP(C4,CoverList!B:B,CoverList!A:A,"") -> Ear_NCB | E4: =IFERROR(VLOOKUP(D4,CoverList!A:C,3,FALSE),"") -> DROPDOWN | F4: 500000 | J4: Y | K4: =IFERROR(VLOOKUP(D4,CoverList!A:D,4,FALSE),"") -> 0
A5: SP | B5: 1234 | C5: Legal Liability to Passengers | D5: =_xlfn.XLOOKUP(C5,CoverList!B:B,CoverList!A:A,"") -> LLTP | E5: =IFERROR(VLOOKUP(D5,CoverList!A:C,3,FALSE),"") -> DROPDOWN | F5: 2000000 | J5: Y | K5: =IFERROR(VLOOKUP(D5,CoverList!A:D,4,FALSE),"") -> 0
A6: SP | B6: 1234 | C6: Earn No Claim Bonus | D6: =_xlfn.XLOOKUP(C6,CoverList!B:B,CoverList!A:A,"") -> Ear_NCB | J6: Y | K6: =IFERROR(VLOOKUP(D6,CoverList!A:D,4,FALSE),"") -> 0
A7: SP | B7: 1234 | C7: Extended Third Party Property Damage | D7: =_xlfn.XLOOKUP(C7,CoverList!B:B,CoverList!A:A,"") -> EX_THI_PA | E7: =IFERROR(VLOOKUP(D7,CoverList!A:C,3,FALSE),"") -> DROPDOWN | J7: Y | K7: =IFERROR(VLOOKUP(D7,CoverList!A:D,4,FALSE),"") -> 0
A8: SP | B8: 1234 | C8: Excluded Items Cover | D8: =_xlfn.XLOOKUP(C8,CoverList!B:B,CoverList!A:A,"") -> EX_IT_COV | E8: =IFERROR(VLOOKUP(D8,CoverList!A:C,3,FALSE),"") -> NORMAL | J8: Y | K8: =IFERROR(VLOOKUP(D8,CoverList!A:D,4,FALSE),"") -> MREXC
A9: SP | B9: 1234 | C9: A.A.C. Membership | D9: =_xlfn.XLOOKUP(C9,CoverList!B:B,CoverList!A:A,"") -> AAC | E9: =IFERROR(VLOOKUP(D9,CoverList!A:C,3,FALSE),"") -> NORMAL | J9: Y | K9: =IFERROR(VLOOKUP(D9,CoverList!A:D,4,FALSE),"") -> MRAAM
A10: SP | B10: 1234 | C10: Multiple Rebate | D10: =_xlfn.XLOOKUP(C10,CoverList!B:B,CoverList!A:A,"") -> MR | E10: =IFERROR(VLOOKUP(D10,CoverList!A:C,3,FALSE),"") -> DROPDOWN | J10: Y | K10: =IFERROR(VLOOKUP(D10,CoverList!A:D,4,FALSE),"") -> 0
A11: SP | B11: 1234 | C11: A.A.C. Membership | D11: =_xlfn.XLOOKUP(C11,CoverList!B:B,CoverList!A:A,"") -> AAC | E11: =IFERROR(VLOOKUP(D11,CoverList!A:C,3,FALSE),"") -> NORMAL | J11: Y | K11: =IFERROR(VLOOKUP(D11,CoverList!A:D,4,FALSE),"") -> MRAAM
E12: =IFERROR(VLOOKUP(D12,CoverList!A:C,3,FALSE),"") | K12: =IFERROR(VLOOKUP(D12,CoverList!A:D,4,FALSE),"")
E13: =IFERROR(VLOOKUP(D13,CoverList!A:C,3,FALSE),"") | K13: =IFERROR(VLOOKUP(D13,CoverList!A:D,4,FALSE),"")
E14: =IFERROR(VLOOKUP(D14,CoverList!A:C,3,FALSE),"") | K14: =IFERROR(VLOOKUP(D14,CoverList!A:D,4,FALSE),"")
E15: =IFERROR(VLOOKUP(D15,CoverList!A:C,3,FALSE),"") | K15: =IFERROR(VLOOKUP(D15,CoverList!A:D,4,FALSE),"")
E16: =IFERROR(VLOOKUP(D16,CoverList!A:C,3,FALSE),"")
E17: =IFERROR(VLOOKUP(D17,CoverList!A:C,3,FALSE),"")
E18: =IFERROR(VLOOKUP(D18,CoverList!A:C,3,FALSE),"")
E20: =IFERROR(VLOOKUP(D20,CoverList!A:C,3,FALSE),"")
E21: =IFERROR(VLOOKUP(D21,CoverList!A:C,3,FALSE),"")
E22: =IFERROR(VLOOKUP(D22,CoverList!A:C,3,FALSE),"")
E23: =IFERROR(VLOOKUP(D23,CoverList!A:C,3,FALSE),"")
E24: =IFERROR(VLOOKUP(D24,CoverList!A:C,3,FALSE),"")
E25: =IFERROR(VLOOKUP(D25,CoverList!A:C,3,FALSE),"")
E26: =IFERROR(VLOOKUP(D26,CoverList!A:C,3,FALSE),"")
E27: =IFERROR(VLOOKUP(D27,CoverList!A:C,3,FALSE),"")
E28: =IFERROR(VLOOKUP(D28,CoverList!A:C,3,FALSE),"")
... E1075: =IFERROR(VLOOKUP(D1075,CoverList!A:C,3,FALSE),"")

Sheet CoverList
A1: COVER_CODE | B1: COVER_NAME | C1: TYPE | D1: RATECODE | H1: POL_ID | I1: POL_NAME | M1: VehicleType | N1: VehicleID | O1: SubCategory | P1: SubCatID | U1: Period | V1: Period ID | W1: Days
A2: AAC | B2: A.A.C. Membership | C2: NORMAL | D2: MRAAM | H2: 1 | I2: Comprehensive Policy | M2: Private Car | N2: A | O2: Private Car | P2: AA0 | U2: 1 | V2: 1 Year | W2: 365
A3: DUT_TREE | B3: Duty Free Vehicle | C3: NORMAL | D3: MRDFV | H3: 2 | I3: Third Party | M3: Hiring Cars | N3: B | O3: HIRING CARS | P3: BB1 | U3: 2 | V3: 8 Months | W3: 240
A4: EX_IT_COV | B4: Excluded Items Cover | C4: NORMAL | D4: MREXC | H4: 3 | I4: Third Party Fire & Theft | M4: Hiring Cars | N4: B | O4: DUAL PURPOSE HIRING | P4: BB2 | U4: 3 | V4: 6 Months | W4: 180
A5: EX_THI_PA | B5: Extended Third Party Property Damage | C5: DROPDOWN | H5: 4 | I5: Fire & Theft | M5: Hiring Cars | N5: B | O5: THREE WHEELER | P5: BB3 | U5: 4 | V5: 4 Months | W5: 120
A6: Ear_NCB | B6: Earn No Claim Bonus | C6: DROPDOWN | H6: 5 | I6: Fire only | M6: Omnibuses/Motor Coaches | N6: CC | O6: OMNIBUSES -SLCTB | P6: CC1 | U6: 5 | V6: 3 Months | W6: 90
A7: Ex_TOW | B7: Extended Towing Charges | C7: VALUE | D7: MRTWC | H7: 6 | I7: Theft only | M7: Omnibuses/Motor Coaches | N7: CC | O7: OTHER BUSES | P7: CC2 | U7: 6 | V7: 2 Months | W7: 60
A8: FLOD | B8: Flood & Natural Perils | C8: NORMAL | D8: MRFLD | M8: Omnibuses/Motor Coaches | N8: CC | O8: DUAL PURPOSE HIRING | P8: CC3 | U8: 7 | V8: 1 Month | W8: 30
A9: SRCC | B9: Strike, Riot & Civil Commotion Risk | C9: NORMAL | D9: MRRCC1 | M9: Miscellaneous Passenger Carrying Vehicles | N9: D | O9: BUSES BELONGS TO INSTITUTES-PRIVATE | P9: DD1 | U9: 8 | V9: 1 Week | W9: 7
A10: TR | B10: Terrorism Risk | C10: NORMAL | D10: MRTR1 | M10: Miscellaneous Passenger Carrying Vehicles | N10: D | O10: BUSES BELONGS TO INSTITUTES-HIRING | P10: DD2
A11: TRA_PLA_LOAD | B11: Trade Palte Loading | C11: NORMAL | M11: Miscellaneous Passenger Carrying Vehicles | N11: D | O11: DUAL/PU.BELONGS TO INSTITUTES-PRIVATE | P11: DD3
A12: ULT_THIPAR_COV | B12: Unlimited tird party cover | C12: NORMAL | M12: Miscellaneous Passenger Carrying Vehicles | N12: D | O12: DUAL/PU.BELONGS TO INSTITUTES-HIRING | P12: DD4
A13: VOL_EX | B13: Voluntary Excess | C13: DROPDOWN | M13: Private Lorry | N13: E | O13: PRIVATE LORRY | P13: EE1
A14: TPSLCTB | B14: Third Party Cover SLCTB | C14: NORMAL | D14: MRCTB | M14: Private Lorry | N14: E | O14: DUAL PURPOSE PRIVATE | P14: EE2
A15: HIR_PU | B15: Hire Purchase | C15: NORMAL | D15: MRHPL | M15: Hiring Lorry | N15: EH | O15: DUAL PURPOSE HIRING (PS. + GOODS) | P15: EE4
A16: LDC | B16: Learner Driver Cover | C16: VALUE | D16: MRLNR | M16: Hiring Lorry | N16: EH | O16: Hiring Lorry | P16: EE3
A17: LDCI | B17: Learner Driver Cover Institutions | C17: NORMAL | D17: MRLNRS | M17: Agricultural/Land Vehicles | N17: F | O17: TRACTORS 2 WH - NOT USING TRAILERS | P17: FF1
A18: LLTP | B18: Legal Liability to Passengers | C18: DROPDOWN | M18: Agricultural/Land Vehicles | N18: F | O18: TRACTORS 2 WH - USING TRAILERS | P18: FF2
A19: REN_VEH | B19: Rent -a-Vehicle | C19: NORMAL | D19: MRRENT | M19: Agricultural/Land Vehicles | N19: F | O19: TRAILERS - USED FOR 2 WH TRACTORS | P19: FF3
A20: GOODS_COV | B20: Goods | C20: DROPDOWN | M20: Agricultural/Land Vehicles | N20: F | O20: TRACTORS 4 WH - NOT USING TRAILERS | P20: FF4
A21: GOOD_SRCC | B21: Civil Commotion Risks on Goods | C21: NORMAL | D21: MRGDRC | M21: Agricultural/Land Vehicles | N21: F | O21: TRACTORS 4 WH - USING TRAILERS | P21: FF5
A22: GOOD_TR | B22: Terrorism Risks on Goods | C22: NORMAL | D22: MRGDTR | M22: Agricultural/Land Vehicles | N22: F | O22: TRAILERS - USED FOR 4 WH TRACTORS | P22: FF6
A23: PAB1_SRCC | B23: Civil Commotion Risks on PAB 1 | C23: NORMAL | D23: MRPRC1 | M23: Motor Cycle | N23: G | O23: Motor Cycle Private Use | P23: GG1
A24: PAB1_TR | B24: Terrorism Risks on PAB 1 | C24: NORMAL | D24: MRPTR1 | M24: Motor Cycle | N24: G | O24: Motor Cycle Good Carrying | P24: GG2
A25: PAB2_SRCC | B25: Civil Commotion Risks on PAB 2 | C25: NORMAL | D25: MRPRC2 | M25: Motor Cycle | N25: G | O25: Motor Cycle on Hire | P25: GG3
A26: PAB2_TR | B26: Terrorism Risks on PAB 2 | C26: NORMAL | D26: MRPTR1 | M26: Special Types | N26: H | O26: CONCRETE MIXERS | P26: HH1
A27: PAB3_SRCC | B27: Civil Commotion Risks on PAB 3 | C27: NORMAL | D27: MRPRC3 | M27: Special Types | N27: H | O27: CRANES | P27: HH1
A28: PAB3_TR | B28: Terrorism Risks on PAB3 | C28: NORMAL | D28: MRPTR3 | M28: Special Types | N28: H | O28: DUMPERS | P28: HH1
A29: PAB_A | B29: PAB Attendant | C29: NORMAL | D29: MRPADCA | M29: Special Types | N29: H | O29: HEARSES | P29: HH2
A30: PAB_C | B30: Personal Accident Benefit - Conductor Cover | C30: NORMAL | D30: MRPADCA | M30: Special Types | N30: H | O30: AMBULANCE | P30: HH2
A31: PAB_CL | B31: PAB Cleaner | C31: NORMAL | D31: MRPADCA | M31: Special Types | N31: H | O31: SPECIAL TYPE PASSENGER CARRYING | P31: HH3
A32: PAB_D | B32: Personal Accident Benefit - Driver Cover | C32: NORMAL | D32: MRPADCA | M32: Special Types | N32: H | O32: CATTERPILLER | P32: HH4
... A49: WS_WI_BR | B49: Windscreen & Window breakage Cover | C49: NORMAL | D49: MRWND | M49: Special Types | N49: H | O49: MOBILE PLANTS/ MOBILE CRANES | P49: HH6
A50: Giv_NCB | B50: Given No Claim Bonus | C50: DROPDOWN | M50: Special Types | N50: H | O50: MOBILE SURGERIES | P50: HH6
A51: HIG_RIK_LOAD | B51: High Risk Loading | C51: VALUE | M51: Special Types | N51: H | O51: X-RAY VEHICLES | P51: HH6
A52: MR | B52: Multiple Rebate | C52: DROPDOWN | M52: Special Types | N52: H | O52: AGRICULTURAL SPRAYES | P52: HH7
A53: BASIC_LOD | B53: Trade Plade basic Loading | C53: VALUE | D53: MRAB | M53: Special Types | N53: H | O53: TEA SPRAYERS / TAR SPRAYES | P53: HH8
A54: DIS_BAS | B54: Discount From Basic | C54: VALUE | M54: Special Types | N54: H | O54: WELDING PLANTS | P54: HH8
A55: SPD | B55: Special Discount | C55: VALUE | M55: Special Types | N55: H | O55: OTHER SPRAYERS | P55: HH8
A56: SPE_LOAD | B56: Special Loading ( Policy Fee) Amount | C56: VALUE | M56: Special Types | N56: H | O56: FIRE BRIGADE VEHICLES | P56: HH9
...

Sheet DropdownValues
A1: LLTP | B1: Ear_NCB | C1: EX_THI_PA | D1: good covers | E1: MR | F1: DIS_BAS
A2: 2000 | B2: 15 | C2: 100000 | D2: Non-Hazardous | E2: 0.025
A3: 10000 | B3: 10 | C3: 300000 | D3: Non-Hazardous/Fire | E3: 05-09 (5%)
A4: 20000 | B4: 20 | C4: 500000 | D4: Non-Hazardous/Extra Hazardous | E4: 10-19 (7.5%)
A5: 50000 | B5: 25 | C5: 1000000 | D5: Hazardous | E5: 20-29 (10%)
A6: 100000 | B6: 30 | C6: 2000000 | D6: Hazardous/Fire | E6: 30-39 (12.5%)
A7: 200000 | B7: 35 | D7: Extra Hazardous | E7: 40-49 (15%)
A8: 500000 | B8: 40 | E8: 50-74 (17.5%)
B9: 45 | E9: 75 & over (20%)
B10: 50
B11: 55
B12: 60
B13: 65
B14: 70

Sheet SubCategoryList
A1: Private Car | B1: HIRING CARS | C1: OMNIBUSES -SLCTB | D1: BUSES BELONGS TO INSTITUTES-PRIVATE | E1: PRIVATE LORRY | F1: Hiring Lorry | G1: TRACTORS 2 WH - NOT USING TRAILERS | H1: Motor Cycle Private Use | I1: CONCRETE MIXERS
B2: DUAL PURPOSE HIRING | C2: OTHER BUSES | D2: BUSES BELONGS TO INSTITUTES-HIRING | E2: DUAL PURPOSE PRIVATE | F2: DUAL PURPOSE HIRING (PS. + GOODS) | G2: TRACTORS 2 WH - USING TRAILERS | H2: Motor Cycle Good Carrying | I2: CRANES
B3: THREE WHEELER | C3: DUAL PURPOSE HIRING | D3: DUAL/PU.BELONGS TO INSTITUTES-PRIVATE | G3: TRAILERS - USED FOR 2 WH TRACTORS | H3: Motor Cycle on Hire | I3: DUMPERS
D4: DUAL/PU.BELONGS TO INSTITUTES-HIRING | G4: TRACTORS 4 WH - NOT USING TRAILERS | I4: HEARSES
G5: TRACTORS 4 WH - USING TRAILERS | I5: AMBULANCE | J5: Trade Plate
G6: TRAILERS - USED FOR 4 WH TRACTORS | I6: SPECIAL TYPE PASSENGER CARRYING
I7: CATTERPILLER
I8: FALK LIFT
I9: LEVELLERS
I10: RIPPERS
I11: ANGELLDOZERS
I12: BULLDOZERS
I13: MECHANICAL NAVIES / EXCAVATORS
I14: BUILDGRADERS
I15: TOWER WAGONS
I16: OTHER CLASSIFIED TRAILERS
I17: ROAD FINISHING MACHINES
I18: DUST CARTS
... I31: FIRE BRIGADE VEHICLES

Sheet Common Filed from front end
A1: Period (PEriod Id) | B1: Drop down with (1 year/ prorate/short period)
A2: Vehicle Or Trailer | B2: Drop down
A3: Is single Vehicle | B3: Radio button
A4: Year | B4: Year of manufacuture (Calender)
A5: Is Policy Fee | B5: on off radio button - 0/1
A6: Tax included | B6: radio button - 1/0
A7: Quotation Type | B7: drop down menu
A8: Is Perment Vehicle | B8: radio button - 1/0
